<mujoco model="ur5e_with_mop">
  <compiler angle="radian" meshdir="assets" autolimits="true"/>
  <option integrator="implicitfast" timestep="0.01"/>

  <!-- ================= DEFAULT SETTINGS ================= -->
  <default>
    <default class="ur5e">
      <default class="visual">
        <geom type="mesh" contype="0" conaffinity="0" group="2"/>
      </default>
      <default class="collision">
        <geom type="capsule" group="3"/>
        <default class="eef_collision">
          <geom type="cylinder"/>
        </default>
      </default>
      <joint axis="0 1 0" range="-6.28319 6.28319"/>
      <default class="joint_limited">
        <joint range="-3.1415 3.1415"/>
      </default>
      <default class="position">
        <position ctrlrange="-6.2831 6.2831" kp="2000" kv="100" forcerange="-150 150"/>
        <default class="position_limited">
          <position ctrlrange="-3.1415 3.1415"/>
        </default>
        <default class="position_small">
          <position kp="500" kv="25" forcerange="-28 28"/>
        </default>
      </default>
    </default>
  </default>

  <!-- ================= MATERIALS + MESHES ================= -->
  <asset>
    <material name="black" rgba="0.033 0.033 0.033 1"/>
    <material name="jointgray" rgba="0.278 0.278 0.278 1"/>
    <material name="linkgray" rgba="0.82 0.82 0.82 1"/>
    <material name="urblue" rgba="0.49 0.678 0.8 1"/>
    <material name="table_material" rgba="0.6 0.4 0.2 1"/>

    <mesh file="base_0.obj"/>
    <mesh file="base_1.obj"/>
    <mesh file="shoulder_0.obj"/>
    <mesh file="shoulder_1.obj"/>
    <mesh file="shoulder_2.obj"/>
    <mesh file="upperarm_0.obj"/>
    <mesh file="upperarm_1.obj"/>
    <mesh file="upperarm_2.obj"/>
    <mesh file="upperarm_3.obj"/>
    <mesh file="forearm_0.obj"/>
    <mesh file="forearm_1.obj"/>
    <mesh file="forearm_2.obj"/>
    <mesh file="forearm_3.obj"/>
    <mesh file="wrist1_0.obj"/>
    <mesh file="wrist1_1.obj"/>
    <mesh file="wrist1_2.obj"/>
    <mesh file="wrist2_0.obj"/>
    <mesh file="wrist2_1.obj"/>
    <mesh file="wrist2_2.obj"/>
    <mesh file="wrist3.obj"/>

    <mesh file="table.obj" scale="2 2 1" name="table"/>

    <mesh name="base_mesh" file="mop_base.obj" scale="0.002 0.002 0.002"/>
    <mesh name="handle_mesh" file="mop_handle.obj" scale="0.002 0.002 0.002"/>
  </asset>

  <!-- ================= WORLD OBJECTS ================= -->
  <worldbody>
    <body name="table" pos="0.3 0 0">
      <inertial mass="50" pos="0 0 0.4" diaginertia="10 10 5"/>
      <geom name="table_visual" type="mesh" mesh="table" material="table_material" class="visual"/>
      <geom name="table_collision" type="mesh" mesh="table" group="3" class="collision"/>
    </body>

    <body name="base" pos="-0.875 -0.1 0.6" quat="1 0 0 1" childclass="ur5e">
      <inertial mass="4" pos="0 0 0" diaginertia="0.0044 0.0044 0.0072"/>
      <geom mesh="base_0" material="black" class="visual"/>
      <geom mesh="base_1" material="jointgray" class="visual"/>

      <body name="shoulder_link" pos="0 0 0.163">
        <inertial mass="3.7" pos="0 0 0" diaginertia="0.0102 0.0102 0.0066"/>
        <joint name="shoulder_pan" axis="0 0 1"/>
        <geom mesh="shoulder_0" material="urblue" class="visual"/>
        <geom mesh="shoulder_1" material="black" class="visual"/>
        <geom mesh="shoulder_2" material="jointgray" class="visual"/>

        <body name="upper_arm_link" pos="0 0.138 0" quat="1 0 1 0">
          <inertial mass="8.39" pos="0 0 0.2125" diaginertia="0.133 0.133 0.015"/>
          <joint name="shoulder_lift"/>
          <geom mesh="upperarm_0" material="linkgray" class="visual"/>
          <geom mesh="upperarm_1" material="black" class="visual"/>
          <geom mesh="upperarm_2" material="jointgray" class="visual"/>
          <geom mesh="upperarm_3" material="urblue" class="visual"/>

          <body name="forearm_link" pos="0 -0.131 0.425">
            <inertial mass="2.27" pos="0 0 0.196" diaginertia="0.031 0.031 0.004"/>
            <joint name="elbow" class="joint_limited"/>
            <geom mesh="forearm_0" material="urblue" class="visual"/>
            <geom mesh="forearm_1" material="linkgray" class="visual"/>
            <geom mesh="forearm_2" material="black" class="visual"/>
            <geom mesh="forearm_3" material="jointgray" class="visual"/>

            <body name="wrist_1_link" pos="0 0 0.392" quat="1 0 1 0">
              <inertial mass="1.219" pos="0 0.127 0" diaginertia="0.0025 0.0025 0.0021"/>
              <joint name="wrist_1"/>
              <geom mesh="wrist1_0" material="black" class="visual"/>
              <geom mesh="wrist1_1" material="urblue" class="visual"/>
              <geom mesh="wrist1_2" material="jointgray" class="visual"/>

              <body name="wrist_2_link" pos="0 0.127 0">
                <inertial mass="1.219" pos="0 0 0.1" diaginertia="0.0025 0.0025 0.0021"/>
                <joint name="wrist_2" axis="0 0 1"/>
                <geom mesh="wrist2_0" material="black" class="visual"/>
                <geom mesh="wrist2_1" material="urblue" class="visual"/>
                <geom mesh="wrist2_2" material="jointgray" class="visual"/>

                <body name="wrist_3_link" pos="0 0 0.1">
                  <inertial mass="0.188" pos="0 0.077 0" diaginertia="0.00013 0.0001 0.0001"/>
                  <joint name="wrist_3"/>
                  <geom mesh="wrist3" material="linkgray" class="visual"/>
                  <site name="ee_site" pos="0 0.08 0" size="0.01" rgba="1 0 0 1"/>

                  <!-- ===== MOP MOUNTED ON THE WRIST ===== -->
                  <body name="mop_mount" pos="0 0.08 0" quat="1 0 0 1">
                    <!-- Combined handle + head -->
                    <body name="mop_tool" pos="0 -0.6 0">
                      <geom type="mesh" mesh="handle_mesh" density="500" friction="0.8 0.1 0.1"/>
                      <body name="mop_head">
                        <!-- Universal swivel joint -->
                        <joint name="mop_socket" type="ball" damping="0.5" limited="false"/>
                        <geom type="mesh" mesh="base_mesh" density="500" friction="0.8 0.1 0.1" pos="0 -0.05 -0.1"/>
                      </body>
                    </body>
                  </body>
                  <!-- ===== END MOP ===== -->
                </body>
              </body>
            </body>
          </body>
        </body>
      </body>
    </body>
  </worldbody>

  <!-- ================= ACTUATORS ================= -->
  <actuator>
    <position class="position" name="shoulder_pan_act" joint="shoulder_pan"/>
    <position class="position" name="shoulder_lift_act" joint="shoulder_lift"/>
    <position class="position_limited" name="elbow_act" joint="elbow"/>
    <position class="position_small" name="wrist_1_act" joint="wrist_1"/>
    <position class="position_small" name="wrist_2_act" joint="wrist_2"/>
    <position class="position_small" name="wrist_3_act" joint="wrist_3"/>
  </actuator>

<!--  &lt;!&ndash; ================= TENDONS ================= &ndash;&gt;-->
<!--  <tendon>-->
<!--    <connect body1="ee_site" body2="mop_mount"-->
<!--             pos1="0 0 0" pos2="0 0 0"-->
<!--             stiffness="50" damping="5"/>-->
<!--  </tendon>-->
</mujoco>
